Workbook

Sheet Pivot tabel
A1: Kota(Proper) | B1: (All)
A3: Sum of Total Harga | B3: Column Labels | J3: Sum of Total Harga | K3: Column Labels
A4: Row Labels | B4: Elektronik | C4: Fashion | D4: Kecantikan | E4: Makanan | F4: Rumah Tangga | G4: Grand Total | K4: 1 | L4: 2 | M4: 3 | N4: 4 | O4: 5 | P4: 6 | Q4: 7 | R4: 8 | S4: 9 | T4: 10 | U4: (blank) | V4: Grand Total
A5: Celana Jeans | C5: 12554000 | G5: 12554000 | J5: Bandung | K5: 1255000 | L5: 2074000 | M5: 1347000 | N5: 720000 | O5: 3250000 | P5: 3858000 | Q5: 4088000 | R5: 6312000 | S5: 6552000 | T5: 6690000 | V5: 36146000
A6: Cokelat Batang | E6: 12405000 | G6: 12405000 | J6: Denpasar | K6: 475000 | L6: 560000 | M6: 1767000 | N6: 3376000 | O6: 2840000 | P6: 2094000 | Q6: 5376000 | R6: 6816000 | S6: 4761000 | T6: 3240000 | V6: 31305000
A7: Gantungan Baju | F7: 10004000 | G7: 10004000 | J7: Jakarta | K7: 244000 | L7: 1020000 | M7: 2445000 | N7: 2520000 | O7: 3475000 | P7: 1704000 | Q7: 4788000 | R7: 2200000 | S7: 1656000 | T7: 7820000 | V7: 27872000
A8: Headphone Bluetooth | B8: 14906000 | G8: 14906000 | J8: Makassar | K8: 533000 | L8: 590000 | M8: 2550000 | N8: 1936000 | O8: 3170000 | P8: 5370000 | Q8: 4123000 | R8: 2880000 | S8: 4230000 | T8: 9630000 | V8: 35012000
A9: Jaket Hoodie | C9: 4866000 | G9: 4866000 | J9: Malang | K9: 963000 | L9: 628000 | M9: 3432000 | N9: 1540000 | O9: 4910000 | P9: 900000 | Q9: 700000 | R9: 3352000 | S9: 3105000 | T9: 5390000 | V9: 24920000
A10: Kabel Data USB-C | B10: 16847000 | G10: 16847000 | J10: Medan | K10: 669000 | L10: 588000 | M10: 1542000 | N10: 1540000 | O10: 2025000 | P10: 4374000 | Q10: 3801000 | R10: 4944000 | S10: 3726000 | T10: 11500000 | V10: 34709000
A11: Kaos Polos | C11: 11386000 | G11: 11386000 | J11: Palembang | K11: 1084000 | L11: 520000 | M11: 1932000 | N11: 2848000 | O11: 3495000 | P11: 2814000 | Q11: 2058000 | R11: 4480000 | S11: 1341000 | T11: 9290000 | V11: 29862000
A12: Kemeja Flanel | C12: 11983000 | G12: 11983000 | J12: Semarang | K12: 325000 | L12: 2458000 | M12: 1629000 | N12: 3820000 | O12: 75000 | P12: 3444000 | Q12: 7196000 | R12: 7184000 | S12: 9819000 | T12: 1640000 | V12: 37590000
A13: Keripik Singkong | E13: 17279000 | G13: 17279000 | J13: Surabaya | K13: 624000 | L13: 1218000 | M13: 2637000 | N13: 1836000 | O13: 725000 | P13: 3798000 | Q13: 3031000 | R13: 4080000 | S13: 6894000 | T13: 3350000 | V13: 28193000
A14: Kopi Sachet 1kg | E14: 9086000 | G14: 9086000 | J14: Yogyakarta | K14: 1388000 | L14: 348000 | M14: 435000 | N14: 1260000 | O14: 2275000 | P14: 2544000 | Q14: 3990000 | R14: 2480000 | S14: 5526000 | T14: 3940000 | V14: 24186000
A15: Lampu LED | F15: 8782000 | G15: 8782000 | J15: (blank)
A16: Lip Cream | D16: 8787000 | G16: 8787000 | J16: Grand Total | K16: 7560000 | L16: 10004000 | M16: 19716000 | N16: 21396000 | O16: 26240000 | P16: 30900000 | Q16: 39151000 | R16: 44728000 | S16: 47610000 | T16: 62490000 | V16: 309795000
A17: Madu Hutan 500ml | E17: 9840000 | G17: 9840000
A18: Masker Wajah | D18: 8231000 | G18: 8231000 | J18: Row Labels | K18: Sum of Total Harga
A19: Micellar Water | D19: 12402000 | G19: 12402000 | J19: Januari | K19: 20634000
A20: Mouse Wireless | B20: 16925000 | G20: 16925000 | J20: Februari | K20: 22932000
A21: Powerbank 10000mAh | B21: 8821000 | G21: 8821000 | J21: Maret | K21: 23285000
A22: Rak Serbaguna | F22: 10044000 | G22: 10044000 | J22: April | K22: 23931000
A23: Sapu Lidi | F23: 9955000 | G23: 9955000 | J23: Mei | K23: 15008000
A24: Serum Vitamin C | D24: 9722000 | G24: 9722000 | J24: Juni | K24: 30269000
A25: Speaker Mini | B25: 27306000 | G25: 27306000 | J25: Juli | K25: 39542000
A26: Sunscreen SPF50 | D26: 17087000 | G26: 17087000 | J26: Agustus | K26: 31239000
A27: Teh Celup Box | E27: 11811000 | G27: 11811000 | J27: September | K27: 30649000
A28: Tempat Sampah | F28: 16257000 | G28: 16257000 | J28: Oktober | K28: 28015000
A29: Topi Baseball | C29: 12509000 | G29: 12509000 | J29: November | K29: 22785000
A30: Grand Total | B30: 84805000 | C30: 53298000 | D30: 56229000 | E30: 60421000 | F30: 55042000 | G30: 309795000 | J30: Desember | K30: 21506000
J31: (blank)
A32: Sum of Total Harga | B32: Column Labels | J32: Grand Total | K32: 309795000
A33: Row Labels | B33: COD | C33: E-Wallet | D33: Kartu Kredit | E33: QRIS | F33: Transfer Bank | G33: (blank) | H33: Grand Total
A34: Dibatalkan | B34: 16900000 | C34: 9365000 | D34: 6630000 | E34: 11276000 | F34: 17268000 | H34: 61439000
A35: Dikirim | B35: 9750000 | C35: 11868000 | D35: 8974000 | E35: 12669000 | F35: 13841000 | H35: 57102000
A36: Diproses | B36: 5455000 | C36: 17563000 | D36: 9222000 | E36: 15604000 | F36: 11610000 | H36: 59454000
A37: Retur | B37: 8335000 | C37: 13370000 | D37: 17479000 | E37: 10947000 | F37: 23318000 | H37: 73449000
A38: Selesai | B38: 10197000 | C38: 13772000 | D38: 10379000 | E38: 9353000 | F38: 14650000 | H38: 58351000
A39: (blank)
A40: Grand Total | B40: 50637000 | C40: 65938000 | D40: 52684000 | E40: 59849000 | F40: 80687000 | H40: 309795000
A42: Sum of Total Harga | B42: Column Labels
...

Sheet Grafik
A3: Row Labels | B3: Sum of Total Harga
A4: Elektronik | B4: 84805000
A5: Fashion | B5: 53298000
A6: Kecantikan | B6: 56229000
A7: Makanan | B7: 60421000
A8: Rumah Tangga | B8: 55042000
A9: Grand Total | B9: 309795000
H11: Row Labels | I11: Sum of Total Harga
H12: COD | I12: 50637000
H13: E-Wallet | I13: 65938000
H14: Kartu Kredit | I14: 52684000
H15: QRIS | I15: 59849000
H16: Transfer Bank | I16: 80687000
H17: Grand Total | I17: 309795000
A18: Row Labels | B18: Sum of Total Harga
A19: Januari | B19: 20634000
A20: Februari | B20: 22932000
A21: Maret | B21: 23285000
A22: April | B22: 23931000
A23: Mei | B23: 15008000
A24: Juni | B24: 30269000
A25: Juli | B25: 39542000
A26: Agustus | B26: 31239000
A27: September | B27: 30649000
A28: Oktober | B28: 28015000
A29: November | B29: 22785000
A30: Desember | B30: 21506000
A31: Grand Total | B31: 309795000

Sheet Jawaban
A3: Sum of Qty | B3: Column Labels
A4: Row Labels | B4: Januari | C4: Februari | D4: Maret | E4: April | F4: Mei | G4: Juni | H4: Juli | I4: Agustus | J4: September | K4: Oktober | L4: November | M4: Desember | N4: Grand Total | O4: Produk apa yang paling laku bulan tertentu?
A5: Serum Vitamin C | B5: 20 | C5: 4 | E5: 10 | F5: 13 | H5: 7 | J5: 7 | K5: 8 | L5: 11 | M5: 34 | N5: 114 | O5: Januari | P5: Sunscreen SPF50
A6: Gantungan Baju | B6: 5 | C6: 2 | D6: 7 | E6: 7 | F6: 7 | G6: 7 | H6: 11 | I6: 2 | J6: 1 | K6: 6 | M6: 28 | N6: 83 | O6: Februari | P6: Madu Hutan 500ml
A7: Tempat Sampah | B7: 18 | C7: 9 | D7: 11 | E7: 9 | H7: 20 | J7: 20 | K7: 28 | L7: 19 | M7: 24 | N7: 158 | O7: Maret | P7: Speaker Mini
A8: Keripik Singkong | B8: 5 | C8: 9 | E8: 1 | F8: 7 | G8: 29 | H8: 38 | I8: 31 | J8: 27 | K8: 6 | L8: 9 | M8: 21 | N8: 183 | O8: April | P8: Kaos Polos
A9: Micellar Water | B9: 10 | C9: 11 | D9: 6 | E9: 3 | F9: 1 | H9: 17 | I9: 17 | J9: 6 | K9: 8 | M9: 18 | N9: 97 | O9: Mei | P9: Sunscreen SPF50
A10: Teh Celup Box | B10: 4 | C10: 9 | D10: 20 | E10: 1 | F10: 4 | G10: 14 | H10: 33 | I10: 17 | J10: 10 | K10: 5 | L10: 9 | M10: 16 | N10: 142 | O10: Juni | P10: Celana Jeans
A11: Topi Baseball | B11: 19 | C11: 25 | D11: 8 | E11: 12 | F11: 6 | H11: 12 | I11: 1 | J11: 8 | K11: 26 | L11: 7 | M11: 15 | N11: 139 | O11: Juli | P11: Speaker Mini
A12: Speaker Mini | B12: 10 | C12: 25 | D12: 29 | E12: 33 | F12: 17 | H12: 38 | I12: 30 | J12: 2 | K12: 25 | L12: 16 | M12: 15 | N12: 240 | O12: Agustus | P12: Keripik Singkong
A13: Jaket Hoodie | B13: 3 | C13: 7 | D13: 4 | E13: 11 | G13: 8 | H13: 8 | I13: 10 | J13: 1 | K13: 2 | L13: 6 | M13: 14 | N13: 74 | O13: September | P13: Mouse Wireleess
A14: Cokelat Batang | B14: 10 | C14: 16 | D14: 9 | E14: 4 | F14: 20 | G14: 14 | I14: 2 | J14: 20 | K14: 11 | L14: 9 | M14: 14 | N14: 129 | O14: Oktober | P14: Tempat Sampah
A15: Headphone Bluetooth | B15: 7 | C15: 16 | D15: 24 | E15: 6 | F15: 15 | G15: 20 | H15: 27 | I15: 13 | J15: 2 | L15: 8 | M15: 12 | N15: 150 | O15: November | P15: Masker Wajah
A16: Lip Cream | B16: 21 | C16: 8 | G16: 14 | I16: 17 | J16: 9 | K16: 10 | L16: 2 | M16: 11 | N16: 92 | O16: Desember | P16: Serum Vitamin C
A17: Madu Hutan 500ml | B17: 8 | C17: 31 | D17: 18 | E17: 9 | G17: 11 | J17: 11 | K17: 5 | L17: 12 | M17: 11 | N17: 116
A18: Rak Serbaguna | B18: 12 | D18: 20 | E18: 5 | F18: 9 | G18: 9 | H18: 11 | I18: 8 | J18: 2 | K18: 17 | L18: 9 | M18: 10 | N18: 112
A19: Masker Wajah | B19: 2 | C19: 9 | D19: 13 | E19: 6 | F19: 5 | G19: 3 | H19: 28 | I19: 10 | J19: 11 | K19: 2 | L19: 27 | M19: 10 | N19: 126
A20: Sunscreen SPF50 | B20: 22 | E20: 10 | F20: 26 | G20: 1 | H20: 17 | I20: 10 | J20: 27 | K20: 27 | L20: 14 | M20: 8 | N20: 162
A21: Kemeja Flanel | B21: 9 | C21: 2 | D21: 7 | E21: 10 | F21: 10 | G21: 7 | H21: 16 | I21: 17 | J21: 5 | K21: 12 | L21: 12 | M21: 8 | N21: 115 | O21: Kirimkan data customer di kota X yang order-nya Selesai, untuk campaign
A22: Kaos Polos | B22: 12 | D22: 23 | E22: 34 | F22: 4 | G22: 13 | H22: 7 | I22: 4 | J22: 14 | K22: 24 | L22: 10 | M22: 7 | N22: 152 | O22: 10375 | P22: Nita Marpaung | Q22: 088562606029 | R22: Denpasar | S22: Kecantikan | T22: Serum Vitamin C | U22: 8 | V22: 35000 | W22: 280000 | X22: 45663 | Y22: Januari | Z22: QRIS | AA22: Selesai
A23: Kabel Data USB-C | B23: 3 | C23: 3 | D23: 14 | E23: 31 | F23: 10 | G23: 5 | H23: 11 | I23: 10 | J23: 10 | K23: 14 | L23: 9 | M23: 7 | N23: 127 | O23: 10342 | P23: Fajar Rahayu | Q23: 088963919195 | R23: Makassar | S23: Rumah Tangga | T23: Rak Serbaguna | U23: 9 | V23: 45000 | W23: 405000 | X23: 45805 | Y23: Mei | Z23: E-Wallet | AA23: Selesai
A24: Lampu LED | B24: 3 | C24: 18 | D24: 17 | F24: 15 | G24: 14 | H24: 17 | I24: 10 | L24: 14 | M24: 4 | N24: 112 | O24: 10177 | P24: Zaki Rahayu | Q24: 08999173816 | R24: Yogyakarta | S24: Kecantikan | T24: Micellar Water | U24: 5 | V24: 0 | W24: 0 | X24: 45691 | Y24: Februari | Z24: Kartu Kredit | AA24: Selesai
A25: Kopi Sachet 1kg | B25: 1 | C25: 22 | D25: 5 | E25: 9 | G25: 17 | H25: 2 | I25: 4 | J25: 30 | K25: 3 | L25: 15 | M25: 3 | N25: 111 | O25: 10372 | P25: Wawan Santoso | Q25: 08745508428 | R25: Denpasar | S25: Elektronik | T25: Speaker Mini | U25: 7 | V25: 25000 | W25: 175000 | X25: 45974 | Y25: November | Z25: COD | AA25: Selesai
A26: Sapu Lidi | B26: 13 | C26: 3 | D26: 3 | E26: 19 | F26: 1 | G26: 26 | H26: 14 | I26: 17 | J26: 2 | K26: 1 | L26: 8 | M26: 2 | N26: 109 | O26: 10031 | P26: Chandra Kusuma | Q26: 088527354549 | R26: Palembang | S26: Rumah Tangga | T26: Gantungan Baju | U26: 10 | V26: 250000 | W26: 2500000 | X26: 45852 | Y26: Juli | Z26: E-Wallet | AA26: Selesai
A27: Mouse Wireless | B27: 6 | C27: 10 | D27: 5 | E27: 22 | F27: 12 | G27: 11 | H27: 30 | I27: 20 | J27: 32 | K27: 27 | L27: 1 | M27: 1 | N27: 177 | O27: 10400 | P27: Vina Setiawan | Q27: 088968549822 | R27: Makassar | S27: Makanan | T27: Teh Celup Box | U27: 3 | V27: 45000 | W27: 135000 | X27: 45994 | Y27: Desember | Z27: Transfer Bank | AA27: Selesai
A28: Celana Jeans | B28: 8 | C28: 11 | D28: 8 | E28: 5 | F28: 20 | G28: 45 | H28: 2 | I28: 22 | J28: 9 | K28: 14 | L28: 20 | N28: 164 | O28: 10403 | P28: Zaki Gunawan | Q28: 088247395003 | R28: Bandung | S28: Fashion | T28: Kaos Polos | U28: 6 | V28: 15000 | W28: 90000 | X28: 45840 | Y28: Juli | Z28: E-Wallet | AA28: Selesai
A29: Powerbank 10000mAh | B29: 18 | F29: 7 | G29: 20 | H29: 19 | I29: 3 | J29: 22 | K29: 5 | L29: 23 | N29: 117 | O29: 10388 | P29: Rian Siregar | Q29: 088304891382 | R29: Semarang | S29: Kecantikan | T29: Masker Wajah | U29: 9 | V29: 99000 | W29: 891000 | X29: 45691 | Y29: Februari | Z29: Kartu Kredit | AA29: Selesai
A30: Grand Total | B30: 249 | C30: 250 | D30: 251 | E30: 257 | F30: 209 | G30: 288 | H30: 385 | I30: 275 | J30: 288 | K30: 286 | L30: 270 | M30: 293 | N30: 3301 | O30: 10406 | P30: Bella Lestari | Q30: 088912868578 | R30: Bandung | S30: Kecantikan | T30: Sunscreen SPF50 | U30: 9 | V30: 199000 | W30: 1791000 | X30: 45908 | Y30: September | Z30: COD | AA30: Selesai
O31: 10599 | P31: Lina Pratama | Q31: 08660464197 | R31: Medan | S31: Kecantikan | T31: Sunscreen SPF50 | U31: 10 | V31: 150000 | W31: 1500000 | X31: 45854 | Y31: Juli | Z31: Kartu Kredit | AA31: Selesai
O32: 10490 | P32: Dian Pratama | Q32: 088787112166 | R32: Makassar | S32: Makanan | T32: Teh Celup Box | U32: 2 | V32: 45000 | W32: 90000 | X32: 45856 | Y32: Juli | Z32: Kartu Kredit | AA32: Selesai
B33: Status | C33: (Multiple Items) | O33: 10448 | P33: Ahmad Hidayat | Q33: 088321840118 | R33: Surabaya | S33: Fashion | T33: Kaos Polos | U33: 9 | V33: 120000 | W33: 1080000 | X33: 45936 | Y33: Oktober | Z33: Transfer Bank | AA33: Selesai
O34: 10042 | P34: Ahmad Nasution | R34: Medan | S34: Kecantikan | T34: Micellar Water | U34: 3 | V34: 50000 | W34: 150000 | X34: 45882 | Y34: Agustus | Z34: Kartu Kredit | AA34: Selesai
B35: Row Labels | C35: Count of Status | E35: Kota mana yang order-nya paling banyak dibatalkan/retur? | O35: 10206 | P35: Indah Pratama | Q35: 088135775949 | R35: Malang | S35: Kecantikan | T35: Lip Cream | U35: 3 | V35: 250000 | W35: 750000 | X35: 45993 | Y35: Desember | Z35: COD | AA35: Selesai
B36: Makassar | C36: 33 | E36: Makassar | O36: 10531 | P36: Citra Saputra | Q36: 08760146723 | R36: Malang | S36: Makanan | T36: Kopi Sachet 1kg | U36: 4 | V36: 45000 | W36: 180000 | X36: 45711 | Y36: Februari | Z36: Kartu Kredit | AA36: Selesai
B37: Medan | C37: 28 | E37: Medan | O37: 10265 | P37: Oki Simatupang | Q37: 088764472649 | R37: Bandung | S37: Makanan | T37: Teh Celup Box | U37: 1 | V37: 150000 | W37: 150000 | X37: 45856 | Y37: Juli | Z37: QRIS | AA37: Selesai
B38: Semarang | C38: 27 | O38: 10201 | P38: Putri Wijaya | Q38: 088336138612 | R38: Bandung | S38: Makanan | T38: Kopi Sachet 1kg | U38: 2 | V38: 35000 | W38: 70000 | X38: 45933 | Y38: Oktober | Z38: QRIS | AA38: Selesai
B39: Bandung | C39: 27 | O39: 10496 | P39: Lina Hidayat | Q39: 088766558685 | R39: Malang | S39: Kecantikan | T39: Lip Cream | U39: 1 | V39: 50000 | W39: 50000 | X39: 45815 | Y39: Juni | Z39: QRIS | AA39: Selesai
B40: Yogyakarta | C40: 25 | O40: 10529 | P40: Tono Halim | Q40: 088870104159 | R40: Malang | S40: Makanan | T40: Madu Hutan 500ml | U40: 1 | V40: 99000 | W40: 99000 | X40: 45811 | Y40: Juni | Z40: Kartu Kredit | AA40: Selesai
B41: Palembang | C41: 25 | O41: 10583 | P41: Sari Siregar | Q41: 088324268774 | R41: Makassar | S41: Rumah Tangga | T41: Sapu Lidi | U41: 5 | V41: 150000 | W41: 750000 | X41: 45820 | Y41: Juni | Z41: QRIS | AA41: Selesai
B42: Surabaya | C42: 24 | O42: 10284 | P42: Fajar Rahayu | Q42: 08290227846 | R42: Jakarta | S42: Elektronik | T42: Mouse Wireless | U42: 7 | V42: 75000 | W42: 525000 | X42: 45911 | Y42: September | Z42: Transfer Bank | AA42: Selesai
...

Sheet Tabel Referensi
A1: Order ID | B1: Name(Proper)Without ID | C1: No HP New | D1: Kota(Proper) | E1: Kategori | F1: Produk | G1: Qty | H1: Harga Satuan | I1: Total Harga | J1: Tanggal Order | K1: Nama Bulan Order | L1: Metode Bayar | M1: Status | N1: Jumlah Order Per Status
A2: 10375 | B2: Nita Marpaung | C2: 088562606029 | D2: Denpasar | E2: Kecantikan | F2: Serum Vitamin C | G2: 8 | H2: 35000 | I2: 280000 | J2: 45663 | K2: Januari | L2: QRIS | M2: Selesai
A3: 10342 | B3: Fajar Rahayu | C3: 088963919195 | D3: Makassar | E3: Rumah Tangga | F3: Rak Serbaguna | G3: 9 | H3: 45000 | I3: 405000 | J3: 45805 | K3: Mei | L3: E-Wallet | M3: Selesai | N3: Selesai | O3: 113
A4: 10232 | B4: Dian Hidayat | C4: 088716947225 | D4: Malang | E4: Makanan | F4: Keripik Singkong | G4: 5 | H4: 75000 | I4: 375000 | J4: 45824 | K4: Juni | L4: QRIS | M4: Dikirim | N4: Dibatalkan | O4: 129
A5: 10144 | B5: Zaki Nugroho | C5: 08210202758 | D5: Bandung | E5: Rumah Tangga | F5: Rak Serbaguna | G5: 8 | H5: 199000 | I5: 1592000 | J5: 45880 | K5: Agustus | L5: Transfer Bank | M5: Dibatalkan | N5: Dikirim | O5: 113
A6: 10344 | B6: Putri Hidayat | C6: 088723246651 | D6: Semarang | E6: Makanan | F6: Cokelat Batang | G6: 7 | H6: 199000 | I6: 1393000 | J6: 45978 | K6: November | L6: Transfer Bank | M6: Retur | N6: Diproses | O6: 122
A7: 10503 | B7: Fitri Hidayat | C7: 08657224029 | D7: Jakarta | E7: Elektronik | F7: Kabel Data USB-C | G7: 2 | H7: 120000 | I7: 240000 | J7: 45978 | K7: November | L7: Transfer Bank | M7: Diproses | N7: Retur | O7: 123
A8: 10367 | B8: Eka Saputra | C8: 088831472760 | D8: Jakarta | E8: Fashion | F8: Kaos Polos | G8: 4 | H8: 120000 | I8: 480000 | J8: 45990 | K8: November | L8: COD | M8: Diproses | O8: 600
A9: 10480 | B9: Joko Simatupang | C9: 088065019179 | D9: Denpasar | E9: Fashion | F9: Jaket Hoodie | G9: 4 | H9: 15000 | I9: 60000 | J9: 45994 | K9: Desember | L9: Transfer Bank | M9: Diproses
A10: 10177 | B10: Zaki Rahayu | C10: 08999173816 | D10: Yogyakarta | E10: Kecantikan | F10: Micellar Water | G10: 5 | H10: 120000 | I10: =G10*H10 -> 600000 | J10: 45691 | K10: Februari | L10: Kartu Kredit | M10: Selesai | N10: Total Penjualan/Kategori | O10: Kecantikan | P10: Rumah Tangga | Q10: Makanan | R10: Elektronik | S10: Fashion
A11: 10091 | B11: Rian Simatupang | C11: 088016245650 | D11: Bandung | E11: Kecantikan | F11: Serum Vitamin C | G11: 1 | H11: 50000 | I11: 50000 | J11: 45970 | K11: November | L11: QRIS | M11: Dikirim | O11: =SUMIF($E$2:$E$601,O10,$I$2:$I$601) -> 56229000 | P11: =SUMIF($E$2:$E$601,P10,$I$2:$I$601) -> 55042000 | Q11: =SUMIF($E$2:$E$601,Q10,$I$2:$I$601) -> 60421000 | R11: =SUMIF($E$2:$E$601,R10,$I$2:$I$601) -> 84805000 | S11: =SUMIF($E$2:$E$601,S10,$I$2:$I$601) -> 53298000
A12: 10008 | B12: Oki Pratama | D12: Bandung | E12: Kecantikan | F12: Serum Vitamin C | G12: 10 | H12: 150000 | I12: 1500000 | J12: 45775 | K12: April | L12: QRIS | M12: Diproses
A13: 10043 | B13: Bella Nugroho | C13: 088274846773 | D13: Semarang | E13: Elektronik | F13: Mouse Wireless | G13: 7 | H13: 25000 | I13: 175000 | J13: 45773 | K13: April | L13: Transfer Bank | M13: Dikirim | N13: Total | O13: =SUM(O11:S11) -> 309795000
A14: 10598 | B14: Gita Rahayu | C14: 088704622681 | D14: Jakarta | E14: Rumah Tangga | F14: Lampu LED | G14: 7 | H14: 35000 | I14: 245000 | J14: 45803 | K14: Mei | L14: E-Wallet | M14: Dikirim
A15: 10544 | B15: Gita Gunawan | C15: 088030102724 | D15: Medan | E15: Fashion | F15: Kaos Polos | G15: 10 | H15: 15000 | I15: 150000 | J15: 45774 | K15: April | L15: Kartu Kredit | M15: Retur
A16: 10111 | B16: Gita Hidayat | C16: 088363854678 | D16: Bandung | E16: Kecantikan | F16: Serum Vitamin C | G16: 4 | H16: 45000 | I16: 180000 | J16: 45691 | K16: Februari | L16: Kartu Kredit | M16: Diproses | N16: Total Penjualan/Kota | O16: Bandung | P16: Denpasar | Q16: Jakarta | R16: Makassar | S16: Malang | T16: Medan | U16: Palembang | V16: Semarang | W16: Surabaya | X16: Yogyakarta
A17: 10051 | B17: Bella Halim | C17: 08236851604 | D17: Denpasar | E17: Fashion | F17: Celana Jeans | G17: 8 | H17: 50000 | I17: 400000 | J17: 45831 | K17: Juni | L17: Transfer Bank | M17: Dikirim | O17: =SUMIF($D$2:$D$601,O16,$I$2:$I$601) -> 36146000 | P17: =SUMIF($D$2:$D$601,P16,$I$2:$I$601) -> 31305000 | Q17: =SUMIF($D$2:$D$601,Q16,$I$2:$I$601) -> 27872000 | R17: =SUMIF($D$2:$D$601,R16,$I$2:$I$601) -> 35012000 | S17: =SUMIF($D$2:$D$601,S16,$I$2:$I$601) -> 24920000 | T17: =SUMIF($D$2:$D$601,T16,$I$2:$I$601) -> 34709000 | U17: =SUMIF($D$2:$D$601,U16,$I$2:$I$601) -> 29862000 | V17: =SUMIF($D$2:$D$601,V16,$I$2:$I$601) -> 37590000 | ... X17: =SUMIF($D$2:$D$601,X16,$I$2:$I$601) -> 24186000
A18: 10097 | B18: Putri Halim | C18: 088415747338 | D18: Semarang | E18: Elektronik | F18: Mouse Wireless | G18: 9 | H18: 99000 | I18: 891000 | J18: 45860 | K18: Juli | L18: E-Wallet | M18: Diproses
A19: 10569 | B19: Erik Santoso | D19: Bandung | E19: Elektronik | F19: Mouse Wireless | G19: 10 | H19: 75000 | I19: 750000 | J19: 45872 | K19: Agustus | L19: QRIS | M19: Retur | N19: Total | O19: =SUM(O17:X17) -> 309795000
A20: 10040 | B20: Hadi Saputra | C20: 088671756551 | D20: Malang | E20: Fashion | F20: Kemeja Flanel | G20: 9 | H20: 250000 | I20: 2250000 | J20: 45884 | K20: Agustus | L20: E-Wallet | M20: Diproses
A21: 10397 | B21: Bella Gunawan | C21: 088997179110 | D21: Bandung | E21: Rumah Tangga | F21: Lampu LED | G21: 6 | H21: 15000 | I21: 90000 | J21: 45828 | K21: Juni | L21: QRIS | M21: Diproses
A22: 10415 | B22: Made Hidayat | C22: 088743027169 | D22: Bandung | E22: Rumah Tangga | F22: Tempat Sampah | G22: 3 | H22: 199000 | I22: 597000 | J22: 45952 | K22: Oktober | L22: E-Wallet | M22: Retur
A23: 10172 | B23: Dian Nasution | D23: Denpasar | E23: Kecantikan | F23: Sunscreen SPF50 | G23: 5 | H23: 25000 | I23: 125000 | J23: 45803 | K23: Mei | L23: Transfer Bank | M23: Dikirim
A24: 10518 | B24: Made Santoso | C24: 088310094318 | D24: Semarang | E24: Makanan | F24: Teh Celup Box | G24: 9 | H24: 99000 | I24: 891000 | J24: 45713 | K24: Februari | L24: Transfer Bank | M24: Diproses
A25: 10231 | B25: Dian Wijaya | C25: 088455884506 | D25: Jakarta | E25: Fashion | F25: Kaos Polos | G25: 4 | H25: 50000 | I25: 200000 | J25: 45666 | K25: Januari | L25: Transfer Bank | M25: Dikirim
A26: 10124 | B26: Lina Pratama | C26: 088167243426 | D26: Bandung | E26: Makanan | F26: Keripik Singkong | G26: 9 | H26: 15000 | I26: 135000 | J26: 45894 | K26: Agustus | L26: COD | M26: Dikirim
A27: 10195 | B27: Rian Gunawan | C27: 088608106200 | D27: Yogyakarta | E27: Rumah Tangga | F27: Gantungan Baju | G27: 10 | H27: 250000 | I27: 2500000 | J27: 46021 | K27: Desember | L27: Kartu Kredit | M27: Retur
A28: 10095 | B28: Rian Siregar | C28: 08368970283 | D28: Bandung | E28: Makanan | F28: Kopi Sachet 1kg | G28: 4 | H28: 15000 | I28: 60000 | J28: 45883 | K28: Agustus | L28: E-Wallet | M28: Dikirim
A29: 10009 | B29: Hadi Kusuma | C29: 088997376311 | D29: Yogyakarta | E29: Makanan | F29: Keripik Singkong | G29: 5 | H29: 250000 | I29: 1250000 | J29: 45817 | K29: Juni | L29: COD | M29: Retur
A30: 10493 | B30: Citra Rahayu | C30: 088423567782 | D30: Makassar | E30: Fashion | F30: Celana Jeans | G30: 3 | H30: 15000 | I30: 45000 | J30: 45705 | K30: Februari | L30: Kartu Kredit | M30: Dibatalkan
A31: 10568 | B31: Gita Marpaung | C31: 088047350476 | D31: Denpasar | E31: Kecantikan | F31: Lip Cream | G31: 7 | H31: 99000 | I31: 693000 | J31: 45884 | K31: Agustus | L31: Kartu Kredit | M31: Dikirim
A32: 10372 | B32: Wawan Santoso | C32: 08745508428 | D32: Denpasar | E32: Elektronik | F32: Speaker Mini | G32: 7 | H32: 25000 | I32: 175000 | J32: 45974 | K32: November | L32: COD | M32: Selesai
A33: 10093 | B33: Rian Siregar | C33: 08825952694 | D33: Medan | E33: Elektronik | F33: Powerbank 10000mAh | G33: 6 | H33: 120000 | I33: 720000 | J33: 45923 | K33: September | L33: Kartu Kredit | M33: Diproses
A34: 10269 | B34: Tono Nasution | C34: 088830220502 | D34: Makassar | E34: Elektronik | F34: Mouse Wireless | G34: 10 | H34: 15000 | I34: 150000 | J34: 45783 | K34: Mei | L34: QRIS | M34: Dibatalkan
A35: 10094 | B35: Rian Nasution | C35: 088097499309 | D35: Semarang | E35: Elektronik | F35: Speaker Mini | G35: 6 | H35: 250000 | I35: 1500000 | J35: 45714 | K35: Februari | L35: Kartu Kredit | M35: Retur
... A42: 10031 | B42: Chandra Kusuma | C42: 088527354549 | D42: Palembang | E42: Rumah Tangga | F42: Gantungan Baju | G42: 10 | H42: 250000 | I42: 2500000 | J42: 45852 | K42: Juli | L42: E-Wallet | M42: Selesai
A43: 10179 | B43: Ahmad Santoso | D43: Jakarta | E43: Makanan | F43: Teh Celup Box | G43: 7 | H43: 99000 | I43: 693000 | J43: 45877 | K43: Agustus | L43: Kartu Kredit | M43: Dikirim
A44: 10400 | B44: Vina Setiawan | C44: 088968549822 | D44: Makassar | E44: Makanan | F44: Teh Celup Box | G44: 3 | H44: 45000 | I44: 135000 | J44: 45994 | K44: Desember | L44: Transfer Bank | M44: Selesai
A45: 10444 | B45: Made Pratama | C45: 088742333059 | D45: Yogyakarta | E45: Elektronik | F45: Speaker Mini | G45: 8 | H45: 250000 | I45: 2000000 | J45: 45741 | K45: Maret | L45: QRIS | M45: Diproses
A46: 10403 | B46: Zaki Gunawan | C46: 088247395003 | D46: Bandung | E46: Fashion | F46: Kaos Polos | G46: 6 | H46: 15000 | I46: 90000 | J46: 45840 | K46: Juli | L46: E-Wallet | M46: Selesai
...

Sheet Tabel Input
A1: Order ID | B1: Nama Customer | C1: No HP | D1: Kota
A2: 10375 | B2: =_xlfn.XLOOKUP(A2,'Tabel Referensi'!$A$2:$A$601,'Tabel Referensi'!$B$2:$B$601) -> Nita Marpaung | C2: =_xlfn.XLOOKUP(A2,'Tabel Referensi'!$A$2:$A$601,'Tabel Referensi'!$C$2:$C$601) -> 088562606029 | D2: =_xlfn.XLOOKUP(A2,'Tabel Referensi'!$A$2:$A$601,'Tabel Referensi'!$D$2:$D$601) -> Denpasar
A3: 10342 | B3: =_xlfn.XLOOKUP(A3,'Tabel Referensi'!$A$2:$A$601,'Tabel Referensi'!$B$2:$B$601) -> Fajar Rahayu | C3: =_xlfn.XLOOKUP(A3,'Tabel Referensi'!$A$2:$A$601,'Tabel Referensi'!$C$2:$C$601) -> 088963919195 | D3: =_xlfn.XLOOKUP(A3,'Tabel Referensi'!$A$2:$A$601,'Tabel Referensi'!$D$2:$D$601) -> Makassar
A4: 10232 | B4: =_xlfn.XLOOKUP(A4,'Tabel Referensi'!$A$2:$A$601,'Tabel Referensi'!$B$2:$B$601) -> Dian Hidayat | C4: =_xlfn.XLOOKUP(A4,'Tabel Referensi'!$A$2:$A$601,'Tabel Referensi'!$C$2:$C$601) -> 088716947225 | D4: =_xlfn.XLOOKUP(A4,'Tabel Referensi'!$A$2:$A$601,'Tabel Referensi'!$D$2:$D$601) -> Malang
A5: 10144 | B5: =_xlfn.XLOOKUP(A5,'Tabel Referensi'!$A$2:$A$601,'Tabel Referensi'!$B$2:$B$601) -> Zaki Nugroho | C5: =_xlfn.XLOOKUP(A5,'Tabel Referensi'!$A$2:$A$601,'Tabel Referensi'!$C$2:$C$601) -> 08210202758 | D5: =_xlfn.XLOOKUP(A5,'Tabel Referensi'!$A$2:$A$601,'Tabel Referensi'!$D$2:$D$601) -> Bandung
A6: 10344 | B6: =_xlfn.XLOOKUP(A6,'Tabel Referensi'!$A$2:$A$601,'Tabel Referensi'!$B$2:$B$601) -> Putri Hidayat | C6: =_xlfn.XLOOKUP(A6,'Tabel Referensi'!$A$2:$A$601,'Tabel Referensi'!$C$2:$C$601) -> 088723246651 | D6: =_xlfn.XLOOKUP(A6,'Tabel Referensi'!$A$2:$A$601,'Tabel Referensi'!$D$2:$D$601) -> Semarang
A7: 10503 | B7: =_xlfn.XLOOKUP(A7,'Tabel Referensi'!$A$2:$A$601,'Tabel Referensi'!$B$2:$B$601) -> Fitri Hidayat | C7: =_xlfn.XLOOKUP(A7,'Tabel Referensi'!$A$2:$A$601,'Tabel Referensi'!$C$2:$C$601) -> 08657224029 | D7: =_xlfn.XLOOKUP(A7,'Tabel Referensi'!$A$2:$A$601,'Tabel Referensi'!$D$2:$D$601) -> Jakarta
A8: 10367 | B8: =_xlfn.XLOOKUP(A8,'Tabel Referensi'!$A$2:$A$601,'Tabel Referensi'!$B$2:$B$601) -> Eka Saputra | C8: =_xlfn.XLOOKUP(A8,'Tabel Referensi'!$A$2:$A$601,'Tabel Referensi'!$C$2:$C$601) -> 088831472760 | D8: =_xlfn.XLOOKUP(A8,'Tabel Referensi'!$A$2:$A$601,'Tabel Referensi'!$D$2:$D$601) -> Jakarta
A9: 10480 | B9: =_xlfn.XLOOKUP(A9,'Tabel Referensi'!$A$2:$A$601,'Tabel Referensi'!$B$2:$B$601) -> Joko Simatupang | C9: =_xlfn.XLOOKUP(A9,'Tabel Referensi'!$A$2:$A$601,'Tabel Referensi'!$C$2:$C$601) -> 088065019179 | D9: =_xlfn.XLOOKUP(A9,'Tabel Referensi'!$A$2:$A$601,'Tabel Referensi'!$D$2:$D$601) -> Denpasar
A10: 10177 | B10: =_xlfn.XLOOKUP(A10,'Tabel Referensi'!$A$2:$A$601,'Tabel Referensi'!$B$2:$B$601) -> Zaki Rahayu | C10: =_xlfn.XLOOKUP(A10,'Tabel Referensi'!$A$2:$A$601,'Tabel Referensi'!$C$2:$C$601) -> 08999173816 | D10: =_xlfn.XLOOKUP(A10,'Tabel Referensi'!$A$2:$A$601,'Tabel Referensi'!$D$2:$D$601) -> Yogyakarta
A11: 10091 | B11: =_xlfn.XLOOKUP(A11,'Tabel Referensi'!$A$2:$A$601,'Tabel Referensi'!$B$2:$B$601) -> Rian Simatupang | C11: =_xlfn.XLOOKUP(A11,'Tabel Referensi'!$A$2:$A$601,'Tabel Referensi'!$C$2:$C$601) -> 088016245650 | D11: =_xlfn.XLOOKUP(A11,'Tabel Referensi'!$A$2:$A$601,'Tabel Referensi'!$D$2:$D$601) -> Bandung
A12: 10008 | B12: =_xlfn.XLOOKUP(A12,'Tabel Referensi'!$A$2:$A$601,'Tabel Referensi'!$B$2:$B$601) -> Oki Pratama | C12: =_xlfn.XLOOKUP(A12,'Tabel Referensi'!$A$2:$A$601,'Tabel Referensi'!$C$2:$C$601) | D12: =_xlfn.XLOOKUP(A12,'Tabel Referensi'!$A$2:$A$601,'Tabel Referensi'!$D$2:$D$601) -> Bandung
A13: 10043 | B13: =_xlfn.XLOOKUP(A13,'Tabel Referensi'!$A$2:$A$601,'Tabel Referensi'!$B$2:$B$601) -> Bella Nugroho | C13: =_xlfn.XLOOKUP(A13,'Tabel Referensi'!$A$2:$A$601,'Tabel Referensi'!$C$2:$C$601) -> 088274846773 | D13: =_xlfn.XLOOKUP(A13,'Tabel Referensi'!$A$2:$A$601,'Tabel Referensi'!$D$2:$D$601) -> Semarang
... A601: 10129 | B601: =_xlfn.XLOOKUP(A601,'Tabel Referensi'!$A$2:$A$601,'Tabel Referensi'!$B$2:$B$601) -> Yani Hidayat | C601: =_xlfn.XLOOKUP(A601,'Tabel Referensi'!$A$2:$A$601,'Tabel Referensi'!$C$2:$C$601) -> 08147859696 | D601: =_xlfn.XLOOKUP(A601,'Tabel Referensi'!$A$2:$A$601,'Tabel Referensi'!$D$2:$D$601) -> Semarang

Sheet Instruksi Latihan
A1: LATIHAN EXCEL - DATA CLEANING & ANALYSIS
A3: Dataset ini SENGAJA dibuat kotor, seperti kondisi data asli di kerjaan.
A4: Masalah yang sengaja ada di dalam data:
A5: 1. Nama customer: ada spasi berlebih, huruf besar/kecil gak konsisten
A6: 2. Kota: ada yang UPPERCASE, lowercase, ada spasi di depan/belakang
A7: 3. No HP: format beda-beda (08xxx, +628xxx, 628xxx), ada yang kosong
A8: 4. Tanggal Order: format beda-beda tiap baris (DD/MM/YYYY, YYYY-MM-DD, dll)
A9: 5. Ada baris duplikat (order yang persis sama muncul 2x)
A10: 6. Ada Qty dan Harga Satuan yang kosong (missing values)
A12: TUGAS LATIHAN (urutan disarankan):
A13: 1. DATA CLEANING
A14: - Bersihkan nama customer: TRIM spasi, samakan jadi Proper Case (pakai PROPER())
... A23: - Pakai SUMIF/SUMIFS: total penjualan per Kategori, atau per Kota
A24: - Pakai XLOOKUP/VLOOKUP: cari data customer tertentu berdasarkan Order ID | D24: =TRIM(C24)
A26: 3. PIVOT TABLE
A27: - Total penjualan per Kategori produk
A28: - Jumlah order per Kota
A29: - Total penjualan per Bulan (group tanggal jadi per bulan)
A30: - Breakdown Status order per Metode Bayara
A32: 4. VISUALISASI
A33: - Bar chart: penjualan per kategori
A34: - Line chart: tren penjualan per bulan
A35: - Pie chart: proporsi metode pembayaran
A37: 5. AD-HOC REQUEST SIMULATION (latihan skenario kerja nyata)
A38: Coba jawab pertanyaan ini pakai data yang udah kamu bersihkan:
A39: - 'Produk apa yang paling laku bulan tertentu?'
... A45: tetap ada buat kamu bandingkan before-after.
